2019-07-19 23:03:28,025 - test - ERROR - test_weather  - 23 - 测试用例执行出错: 查询天气
Traceback (most recent call last):
  File "/Applications/PyCharm CE.app/Contents/helpers/pycharm/teamcity/diff_tools.py", line 32, in _patched_equals
    old(self, first, second, msg)
  File "/usr/local/Cellar/python/3.7.0/Frameworks/Python.framework/Versions/3.7/lib/python3.7/unittest/case.py", line 839, in assertEqual
    assertion_func(first, second, msg=msg)
  File "/usr/local/Cellar/python/3.7.0/Frameworks/Python.framework/Versions/3.7/lib/python3.7/unittest/case.py", line 832, in _baseAssertEqual
    raise self.failureException(msg)
AssertionError: 403 != 200

During handling of the above exception, another exception occurred:

Traceback (most recent call last):
  File "/Users/qihe/Downloads/Learning/homework/python+requests/TestCase/test_weather.py", line 18, in test_weather
    test1 = self.assertEqual(status_code, 200)
  File "/Applications/PyCharm CE.app/Contents/helpers/pycharm/teamcity/diff_tools.py", line 38, in _patched_equals
    raise error
teamcity.diff_tools.EqualsAssertionError:  :: 403 != 200
